Workbook

Sheet Problem Statement
A1: Given Dataset containing employee details with employee-code, experience, department, city, salaries etc. You are suppose to use logical functions according to the actions with condition given below and evaluate the solution into the logical sheet given below.
B3: Actions | C3: Condition
A4: Action 1 | B4: Terminate the employee whose performance is | C4: Very Poor
A5: Action 2 | B5: Give 5% bonus to employee having rating as | C5: Very Good
A6: Action 3 | B6: Display the salary grouping based on condition | C6: Less than 40000-Low 41000 to 80000- Mid Above 80000- High
A7: Action 4 | B7: Give option of Work from Home to | C7: HR and Mumbai
A8: Action 5 | B8: Give option of Work from Home to | C8: HR or Finance
A9: Action 6 | B9: Give Increment based on performance | C9: Very Good:15% Good: 12% Average: 10% Else: Not applicable
A13: Click here to | B13: Go to the sheet- Logical

Sheet Logical
A1: Employee Details
A3: Emp Code | B3: Emp First Name | C3: Emp Middle Name | D3: Emp Last Name | E3: Date of Birth | F3: Date of Joining | G3: Experience | H3: Branch Code | I3: Branch Name | J3: Phone No. | K3: Dept Code | L3: Department Name | M3: Education | N3: Rating | O3: Gender | P3: Total Salary | Q3: Action 1 | R3: Action 2 | S3: Action 3 | T3: Action 4 | U3: Action 5 | V3: Action 6
A4: EMP-95480 | B4: YASH | C4: ADESH | D4: KUMAR | E4: 21976 | F4: 41248 | G4: 5 | H4: Loc-1003 | I4: NAGPUR | J4: 79203827xx | K4: Dept-103 | L4: FINANCE | M4: Mcom | N4: Very Poor | O4: Male | P4: 82746.99 | Q4: =IF(N4="very poor","Terminate","Stay") -> Terminate | R4: =IF(Logical!N4="very good","5% increment","no increment") -> no increment | S4: {=_xlfn.IFS(P4<40000,"low",P4>80000,"high",P4,"mid")} -> high | T4: =IF(AND(L4="hr",I4="mumbai"),"give work from home","no work from home") -> no work from home | U4: =IF(OR(L4="finance",Logical!L4="hr"),"give work from home","no work from home") -> give work from home | V4: {=_xlfn.IFS(N4="very good","15% increment",N4="good","12% increment",N4="average","10% increment")} -> #N/A
A5: EMP-95444 | B5: SUKANYA | C5: AJAY | D5: DHANANJAY | E5: 28282 | F5: 41187 | G5: 6 | H5: Loc-1001 | I5: DELHI | J5: 79221649xx | K5: Dept-103 | L5: FINANCE | M5: MBA | N5: Good | O5: Female | P5: 36895.95 | Q5: =IF(N5="very poor","Terminate","Stay") -> Stay | R5: =IF(Logical!N5="very good","5% increment","no increment") -> no increment | S5: {=_xlfn.IFS(P5<40000,"low",P5>80000,"high",P5,"mid")} -> low | T5: =IF(AND(L5="hr",I5="mumbai"),"give work from home","no work from home") -> no work from home | U5: =IF(OR(L5="finance",Logical!L5="hr"),"give work from home","no work from home") -> give work from home | V5: {=_xlfn.IFS(N5="very good","15% increment",N5="good","12% increment",N5="average","10% increment")} -> 12% increment
A6: EMP-95504 | B6: VAIBHAVI | C6: AJAY | D6: SHEKHAR | E6: 21976 | F6: 41218 | G6: 8 | H6: Loc-1004 | I6: MUMBAI | J6: 79212738xx | K6: Dept-102 | L6: HR | M6: ICWA | N6: Very Poor | O6: Female | P6: 141555.6 | Q6: =IF(N6="very poor","Terminate","Stay") -> Terminate | R6: =IF(Logical!N6="very good","5% increment","no increment") -> no increment | S6: {=_xlfn.IFS(P6<40000,"low",P6>80000,"high",P6,"mid")} -> high | T6: =IF(AND(L6="hr",I6="mumbai"),"give work from home","no work from home") -> give work from home | U6: =IF(OR(L6="finance",Logical!L6="hr"),"give work from home","no work from home") -> give work from home | V6: {=_xlfn.IFS(N6="very good","15% increment",N6="good","12% increment",N6="average","10% increment")} -> #N/A
A7: EMP-95462 | B7: SHIVANI | C7: AJIT | D7: RITESH | E7: 28282 | F7: 41157 | G7: 7 | H7: Loc-1002 | I7: BANGALORE | J7: 79230559xx | K7: Dept-103 | L7: FINANCE | M7: M S | N7: Good | O7: Female | P7: 91631.7 | Q7: =IF(N7="very poor","Terminate","Stay") -> Stay | R7: =IF(Logical!N7="very good","5% increment","no increment") -> no increment | S7: {=_xlfn.IFS(P7<40000,"low",P7>80000,"high",P7,"mid")} -> high | T7: =IF(AND(L7="hr",I7="mumbai"),"give work from home","no work from home") -> no work from home | U7: =IF(OR(L7="finance",Logical!L7="hr"),"give work from home","no work from home") -> give work from home | V7: {=_xlfn.IFS(N7="very good","15% increment",N7="good","12% increment",N7="average","10% increment")} -> 12% increment
A8: EMP-95481 | B8: SHEETAL | C8: ANAND | D8: AWALGAONKAR | E8: 28894 | F8: 41126 | G8: 8 | H8: Loc-1003 | I8: NAGPUR | J8: 79239470xx | K8: Dept-101 | L8: PRODUCTION | M8: B.E | N8: Not Rated | O8: Female | P8: 25710.12 | Q8: =IF(N8="very poor","Terminate","Stay") -> Stay | R8: =IF(Logical!N8="very good","5% increment","no increment") -> no increment | S8: {=_xlfn.IFS(P8<40000,"low",P8>80000,"high",P8,"mid")} -> low | T8: =IF(AND(L8="hr",I8="mumbai"),"give work from home","no work from home") -> no work from home | U8: =IF(OR(L8="finance",Logical!L8="hr"),"give work from home","no work from home") -> no work from home | V8: {=_xlfn.IFS(N8="very good","15% increment",N8="good","12% increment",N8="average","10% increment")} -> #N/A
A9: EMP-95505 | B9: SAYANTAN | C9: ANAND | D9: GAWANDE | E9: 28894 | F9: 41095 | G9: 5 | H9: Loc-1004 | I9: MUMBAI | J9: 79248381xx | K9: Dept-103 | L9: FINANCE | M9: PGDBM | N9: Average | O9: Male | P9: 116361.09 | Q9: =IF(N9="very poor","Terminate","Stay") -> Stay | R9: =IF(Logical!N9="very good","5% increment","no increment") -> no increment | S9: {=_xlfn.IFS(P9<40000,"low",P9>80000,"high",P9,"mid")} -> high | T9: =IF(AND(L9="hr",I9="mumbai"),"give work from home","no work from home") -> no work from home | U9: =IF(OR(L9="finance",Logical!L9="hr"),"give work from home","no work from home") -> give work from home | V9: {=_xlfn.IFS(N9="very good","15% increment",N9="good","12% increment",N9="average","10% increment")} -> 10% increment
A10: EMP-95544 | B10: SANTOSH | C10: ANANDKUMAR | D10: GADEKAR | E10: 29222 | F10: 41065 | G10: 5 | H10: Loc-1005 | I10: CHENNAI | J10: 79257292xx | K10: Dept-104 | L10: MARKETING | M10: B.E | N10: Very Poor | O10: Male | P10: 90048.15 | Q10: =IF(N10="very poor","Terminate","Stay") -> Terminate | R10: =IF(Logical!N10="very good","5% increment","no increment") -> no increment | S10: {=_xlfn.IFS(P10<40000,"low",P10>80000,"high",P10,"mid")} -> high | T10: =IF(AND(L10="hr",I10="mumbai"),"give work from home","no work from home") -> no work from home | U10: =IF(OR(L10="finance",Logical!L10="hr"),"give work from home","no work from home") -> no work from home | V10: {=_xlfn.IFS(N10="very good","15% increment",N10="good","12% increment",N10="average","10% increment")} -> #N/A
A11: EMP-95506 | B11: SANKET | C11: ANIL | D11: KELKAR | E11: 29222 | F11: 41034 | G11: 6 | H11: Loc-1004 | I11: MUMBAI | J11: 79266203xx | K11: Dept-105 | L11: ADMIN | M11: PGDBM | N11: Good | O11: Male | P11: 97552.8 | Q11: =IF(N11="very poor","Terminate","Stay") -> Stay | R11: =IF(Logical!N11="very good","5% increment","no increment") -> no increment | S11: {=_xlfn.IFS(P11<40000,"low",P11>80000,"high",P11,"mid")} -> high | T11: =IF(AND(L11="hr",I11="mumbai"),"give work from home","no work from home") -> no work from home | U11: =IF(OR(L11="finance",Logical!L11="hr"),"give work from home","no work from home") -> no work from home | V11: {=_xlfn.IFS(N11="very good","15% increment",N11="good","12% increment",N11="average","10% increment")} -> 12% increment
A12: EMP-95545 | B12: SACHIN | C12: ANIL | D12: SHARMA | E12: 29984 | F12: 41004 | G12: 7 | H12: Loc-1005 | I12: CHENNAI | J12: 79275114xx | K12: Dept-105 | L12: ADMIN | M12: MCOM | N12: Poor | O12: Male | P12: 51597.72 | Q12: =IF(N12="very poor","Terminate","Stay") -> Stay | R12: =IF(Logical!N12="very good","5% increment","no increment") -> no increment | S12: {=_xlfn.IFS(P12<40000,"low",P12>80000,"high",P12,"mid")} -> mid | T12: =IF(AND(L12="hr",I12="mumbai"),"give work from home","no work from home") -> no work from home | U12: =IF(OR(L12="finance",Logical!L12="hr"),"give work from home","no work from home") -> no work from home | V12: {=_xlfn.IFS(N12="very good","15% increment",N12="good","12% increment",N12="average","10% increment")} -> #N/A
A13: EMP-95507 | B13: RITIKA | C13: ARJUN | D13: FADKE | E13: 29984 | F13: 40973 | G13: 8 | H13: Loc-1004 | I13: MUMBAI | J13: 79284025xx | K13: Dept-102 | L13: HR | M13: MBA | N13: Very Poor | O13: Female | P13: 105103.35 | Q13: =IF(N13="very poor","Terminate","Stay") -> Terminate | R13: =IF(Logical!N13="very good","5% increment","no increment") -> no increment | S13: {=_xlfn.IFS(P13<40000,"low",P13>80000,"high",P13,"mid")} -> high | T13: =IF(AND(L13="hr",I13="mumbai"),"give work from home","no work from home") -> give work from home | U13: =IF(OR(L13="finance",Logical!L13="hr"),"give work from home","no work from home") -> give work from home | V13: {=_xlfn.IFS(N13="very good","15% increment",N13="good","12% increment",N13="average","10% increment")} -> #N/A
A14: EMP-95546 | B14: RITESH | C14: ASHISH | D14: GARUD | E14: 30811 | F14: 40944 | G14: 6 | H14: Loc-1005 | I14: CHENNAI | J14: 79292936xx | K14: Dept-104 | L14: MARKETING | M14: Msc | N14: Average | O14: Male | P14: 147340.53 | Q14: =IF(N14="very poor","Terminate","Stay") -> Stay | R14: =IF(Logical!N14="very good","5% increment","no increment") -> no increment | S14: {=_xlfn.IFS(P14<40000,"low",P14>80000,"high",P14,"mid")} -> high | T14: =IF(AND(L14="hr",I14="mumbai"),"give work from home","no work from home") -> no work from home | U14: =IF(OR(L14="finance",Logical!L14="hr"),"give work from home","no work from home") -> no work from home | V14: {=_xlfn.IFS(N14="very good","15% increment",N14="good","12% increment",N14="average","10% increment")} -> 10% increment
A15: EMP-95508 | B15: PRIYANKA | C15: ASHOK | D15: DESHPANDE | E15: 30811 | F15: 40913 | G15: 7 | H15: Loc-1004 | I15: MUMBAI | J15: 79301847xx | K15: Dept-101 | L15: PRODUCTION | M15: CS | N15: Very Poor | O15: Female | P15: 109783.62 | Q15: =IF(N15="very poor","Terminate","Stay") -> Terminate | R15: =IF(Logical!N15="very good","5% increment","no increment") -> no increment | S15: {=_xlfn.IFS(P15<40000,"low",P15>80000,"high",P15,"mid")} -> high | T15: =IF(AND(L15="hr",I15="mumbai"),"give work from home","no work from home") -> no work from home | U15: =IF(OR(L15="finance",Logical!L15="hr"),"give work from home","no work from home") -> no work from home | V15: {=_xlfn.IFS(N15="very good","15% increment",N15="good","12% increment",N15="average","10% increment")} -> #N/A
... A35: EMP-95512 | B35: AKSHAT | C35: DILIP | D35: SHAH | E35: 32999 | F35: 42129 | G35: 6 | H35: Loc-1004 | I35: MUMBAI | J35: 79480065xx | K35: Dept-101 | L35: PRODUCTION | M35: M S | N35: Good | O35: Male | P35: 62928.9 | Q35: =IF(N35="very poor","Terminate","Stay") -> Stay | R35: =IF(Logical!N35="very good","5% increment","no increment") -> no increment | S35: {=_xlfn.IFS(P35<40000,"low",P35>80000,"high",P35,"mid")} -> mid | T35: =IF(AND(L35="hr",I35="mumbai"),"give work from home","no work from home") -> no work from home | U35: =IF(OR(L35="finance",Logical!L35="hr"),"give work from home","no work from home") -> no work from home | V35: {=_xlfn.IFS(N35="very good","15% increment",N35="good","12% increment",N35="average","10% increment")} -> 12% increment
A36: EMP-95551 | B36: AKASH | C36: DINESH | D36: SHAH | E36: 32999 | F36: 42830 | G36: 7 | H36: Loc-1005 | I36: CHENNAI | J36: 79488976xx | K36: Dept-101 | L36: PRODUCTION | M36: M.E | N36: Good | O36: Male | Q36: =IF(N36="very poor","Terminate","Stay") -> Stay | R36: =IF(Logical!N36="very good","5% increment","no increment") -> no increment | S36: {=_xlfn.IFS(P36<40000,"low",P36>80000,"high",P36,"mid")} -> high | T36: =IF(AND(L36="hr",I36="mumbai"),"give work from home","no work from home") -> no work from home | U36: =IF(OR(L36="finance",Logical!L36="hr"),"give work from home","no work from home") -> no work from home | V36: {=_xlfn.IFS(N36="very good","15% increment",N36="good","12% increment",N36="average","10% increment")} -> 12% increment
A37: EMP-95552 | B37: ADITI | C37: FEROZ | D37: SHAH | E37: 33030 | F37: 43164 | G37: 8 | H37: Loc-1005 | I37: CHENNAI | J37: 79497886xx | K37: Dept-102 | L37: HR | M37: MBA | N37: Average | O37: Female | P37: 135857.88 | Q37: =IF(N37="very poor","Terminate","Stay") -> Stay | R37: =IF(Logical!N37="very good","5% increment","no increment") -> no increment | S37: {=_xlfn.IFS(P37<40000,"low",P37>80000,"high",P37,"mid")} -> high | T37: =IF(AND(L37="hr",I37="mumbai"),"give work from home","no work from home") -> no work from home | U37: =IF(OR(L37="finance",Logical!L37="hr"),"give work from home","no work from home") -> give work from home | V37: {=_xlfn.IFS(N37="very good","15% increment",N37="good","12% increment",N37="average","10% increment")} -> 10% increment
A38: EMP-95514 | B38: YOGESH | C38: GAJENDRA | D38: SHAH | E38: 33060 | F38: 41310 | G38: 5 | H38: Loc-1004 | I38: MUMBAI | J38: 79506797xx | K38: Dept-101 | L38: PRODUCTION | M38: B.E | N38: Very Good | O38: Male | P38: 143448.21 | Q38: =IF(N38="very poor","Terminate","Stay") -> Stay | R38: =IF(Logical!N38="very good","5% increment","no increment") -> 5% increment | S38: {=_xlfn.IFS(P38<40000,"low",P38>80000,"high",P38,"mid")} -> high | T38: =IF(AND(L38="hr",I38="mumbai"),"give work from home","no work from home") -> no work from home | U38: =IF(OR(L38="finance",Logical!L38="hr"),"give work from home","no work from home") -> no work from home | V38: {=_xlfn.IFS(N38="very good","15% increment",N38="good","12% increment",N38="average","10% increment")} -> 15% increment
A39: EMP-95553 | B39: YOGESH | C39: GAUTAM | D39: SHAH | E39: 33091 | F39: 41279 | G39: 6 | H39: Loc-1005 | I39: CHENNAI | J39: 79515708xx | K39: Dept-102 | L39: HR | M39: PGDBM | N39: Poor | O39: Male | P39: 26964.72 | Q39: =IF(N39="very poor","Terminate","Stay") -> Stay | R39: =IF(Logical!N39="very good","5% increment","no increment") -> no increment | S39: {=_xlfn.IFS(P39<40000,"low",P39>80000,"high",P39,"mid")} -> low | T39: =IF(AND(L39="hr",I39="mumbai"),"give work from home","no work from home") -> no work from home | U39: =IF(OR(L39="finance",Logical!L39="hr"),"give work from home","no work from home") -> give work from home | V39: {=_xlfn.IFS(N39="very good","15% increment",N39="good","12% increment",N39="average","10% increment")} -> #N/A
A40: EMP-95515 | B40: VIPUL | C40: GOPAL | D40: SAWANT | E40: 33122 | F40: 43074 | G40: 7 | H40: Loc-1004 | I40: MUMBAI | J40: 79524619xx | K40: Dept-103 | L40: FINANCE | M40: Bsc | N40: Good | O40: Male | P40: 126960.93 | Q40: =IF(N40="very poor","Terminate","Stay") -> Stay | R40: =IF(Logical!N40="very good","5% increment","no increment") -> no increment | S40: {=_xlfn.IFS(P40<40000,"low",P40>80000,"high",P40,"mid")} -> high | T40: =IF(AND(L40="hr",I40="mumbai"),"give work from home","no work from home") -> no work from home | U40: =IF(OR(L40="finance",Logical!L40="hr"),"give work from home","no work from home") -> give work from home | V40: {=_xlfn.IFS(N40="very good","15% increment",N40="good","12% increment",N40="average","10% increment")} -> 12% increment
A41: EMP-95554 | B41: SUJEYA | C41: GUPTA | D41: SAWADE | E41: 33152 | F41: 41218 | G41: 8 | H41: Loc-1005 | I41: CHENNAI | J41: 79533530xx | K41: Dept-104 | L41: MARKETING | M41: CS | N41: Very Poor | O41: Male | P41: 18499.23 | Q41: =IF(N41="very poor","Terminate","Stay") -> Terminate | R41: =IF(Logical!N41="very good","5% increment","no increment") -> no increment | S41: {=_xlfn.IFS(P41<40000,"low",P41>80000,"high",P41,"mid")} -> low | T41: =IF(AND(L41="hr",I41="mumbai"),"give work from home","no work from home") -> no work from home | U41: =IF(OR(L41="finance",Logical!L41="hr"),"give work from home","no work from home") -> no work from home | V41: {=_xlfn.IFS(N41="very good","15% increment",N41="good","12% increment",N41="average","10% increment")} -> #N/A
A42: EMP-95448 | B42: SOMAY | C42: GYARSILAL | D42: SATPUTE | E42: 33183 | F42: 41187 | G42: 6 | H42: Loc-1001 | I42: DELHI | J42: 79542441xx | K42: Dept-102 | L42: HR | M42: MBA | N42: Poor | O42: Male | P42: 77344.56 | Q42: =IF(N42="very poor","Terminate","Stay") -> Stay | R42: =IF(Logical!N42="very good","5% increment","no increment") -> no increment | S42: {=_xlfn.IFS(P42<40000,"low",P42>80000,"high",P42,"mid")} -> mid | T42: =IF(AND(L42="hr",I42="mumbai"),"give work from home","no work from home") -> no work from home | U42: =IF(OR(L42="finance",Logical!L42="hr"),"give work from home","no work from home") -> give work from home | V42: {=_xlfn.IFS(N42="very good","15% increment",N42="good","12% increment",N42="average","10% increment")} -> #N/A
A43: EMP-95466 | B43: SHWETA | C43: HAMBIRRAO | D43: SATHE | E43: 33213 | F43: 41157 | G43: 7 | H43: Loc-1002 | I43: BANGALORE | J43: 79551352xx | K43: Dept-102 | L43: HR | M43: M S | N43: Good | O43: Female | P43: 140371.38 | Q43: =IF(N43="very poor","Terminate","Stay") -> Stay | R43: =IF(Logical!N43="very good","5% increment","no increment") -> no increment | S43: {=_xlfn.IFS(P43<40000,"low",P43>80000,"high",P43,"mid")} -> high | T43: =IF(AND(L43="hr",I43="mumbai"),"give work from home","no work from home") -> no work from home | U43: =IF(OR(L43="finance",Logical!L43="hr"),"give work from home","no work from home") -> give work from home | V43: {=_xlfn.IFS(N43="very good","15% increment",N43="good","12% increment",N43="average","10% increment")} -> 12% increment
A44: EMP-95486 | B44: Shubhrata | C44: HANUMANT | D44: SANKHLA | E44: 33244 | F44: 44413 | G44: 8 | H44: Loc-1003 | I44: NAGPUR | J44: 79560263xx | K44: Dept-105 | L44: ADMIN | M44: M S | N44: Good | O44: Female | P44: 34740.18 | Q44: =IF(N44="very poor","Terminate","Stay") -> Stay | R44: =IF(Logical!N44="very good","5% increment","no increment") -> no increment | S44: {=_xlfn.IFS(P44<40000,"low",P44>80000,"high",P44,"mid")} -> low | T44: =IF(AND(L44="hr",I44="mumbai"),"give work from home","no work from home") -> no work from home | U44: =IF(OR(L44="finance",Logical!L44="hr"),"give work from home","no work from home") -> no work from home | V44: {=_xlfn.IFS(N44="very good","15% increment",N44="good","12% increment",N44="average","10% increment")} -> 12% increment
A45: EMP-95516 | B45: SHASHWAT | C45: HARESH | D45: SALUNKE | E45: 33275 | F45: 44017 | G45: 5 | H45: Loc-1004 | I45: MUMBAI | J45: 79569174xx | K45: Dept-105 | L45: ADMIN | M45: MBA | N45: Very Poor | O45: Male | P45: 110368.08 | Q45: =IF(N45="very poor","Terminate","Stay") -> Terminate | R45: =IF(Logical!N45="very good","5% increment","no increment") -> no increment | S45: {=_xlfn.IFS(P45<40000,"low",P45>80000,"high",P45,"mid")} -> high | T45: =IF(AND(L45="hr",I45="mumbai"),"give work from home","no work from home") -> no work from home | U45: =IF(OR(L45="finance",Logical!L45="hr"),"give work from home","no work from home") -> no work from home | V45: {=_xlfn.IFS(N45="very good","15% increment",N45="good","12% increment",N45="average","10% increment")} -> #N/A
A46: EMP-95487 | B46: RUSHABH | C46: HEMANT | D46: RODE | E46: 33303 | F46: 41065 | G46: 6 | H46: Loc-1003 | I46: NAGPUR | J46: 79578085xx | K46: Dept-102 | L46: HR | M46: BCA | N46: Poor | O46: Male | P46: 43725.87 | Q46: =IF(N46="very poor","Terminate","Stay") -> Stay | R46: =IF(Logical!N46="very good","5% increment","no increment") -> no increment | S46: {=_xlfn.IFS(P46<40000,"low",P46>80000,"high",P46,"mid")} -> mid | T46: =IF(AND(L46="hr",I46="mumbai"),"give work from home","no work from home") -> no work from home | U46: =IF(OR(L46="finance",Logical!L46="hr"),"give work from home","no work from home") -> give work from home | V46: {=_xlfn.IFS(N46="very good","15% increment",N46="good","12% increment",N46="average","10% increment")} -> #N/A
A47: EMP-95517 | B47: RUCHIRA | C47: HUSSAIN | D47: REDDY | E47: 33334 | F47: 41034 | G47: 7 | H47: Loc-1004 | I47: MUMBAI | J47: 79586995xx | K47: Dept-101 | L47: PRODUCTION | M47: PGDBM | N47: Poor | O47: Female | P47: 144285.12 | Q47: =IF(N47="very poor","Terminate","Stay") -> Stay | R47: =IF(Logical!N47="very good","5% increment","no increment") -> no increment | S47: {=_xlfn.IFS(P47<40000,"low",P47>80000,"high",P47,"mid")} -> high | T47: =IF(AND(L47="hr",I47="mumbai"),"give work from home","no work from home") -> no work from home | U47: =IF(OR(L47="finance",Logical!L47="hr"),"give work from home","no work from home") -> no work from home | V47: {=_xlfn.IFS(N47="very good","15% increment",N47="good","12% increment",N47="average","10% increment")} -> #N/A
A48: EMP-95449 | B48: ROHIT | C48: ISHWAR | D48: RATHI | E48: 33364 | F48: 44291 | G48: 8 | H48: Loc-1001 | I48: DELHI | J48: 79595906xx | K48: Dept-104 | L48: MARKETING | M48: BCA | N48: Very Good | O48: Male | P48: 88876.17 | Q48: =IF(N48="very poor","Terminate","Stay") -> Stay | R48: =IF(Logical!N48="very good","5% increment","no increment") -> 5% increment | S48: {=_xlfn.IFS(P48<40000,"low",P48>80000,"high",P48,"mid")} -> high | T48: =IF(AND(L48="hr",I48="mumbai"),"give work from home","no work from home") -> no work from home | U48: =IF(OR(L48="finance",Logical!L48="hr"),"give work from home","no work from home") -> no work from home | V48: {=_xlfn.IFS(N48="very good","15% increment",N48="good","12% increment",N48="average","10% increment")} -> 15% increment
... A60: EMP-95468 | B60: KAWALJEET | C60: KUMAR | D60: PALAN | E60: 33730 | F60: 41065 | G60: 6 | H60: Loc-1002 | I60: BANGALORE | J60: 79702837xx | K60: Dept-104 | L60: MARKETING | M60: MBA | N60: Average | O60: Female | P60: 20962.53 | Q60: =IF(N60="very poor","Terminate","Stay") -> Stay | R60: =IF(Logical!N60="very good","5% increment","no increment") -> no increment | S60: {=_xlfn.IFS(P60<40000,"low",P60>80000,"high",P60,"mid")} -> low | T60: =IF(AND(L60="hr",I60="mumbai"),"give work from home","no work from home") -> no work from home | U60: =IF(OR(L60="finance",Logical!L60="hr"),"give work from home","no work from home") -> no work from home | V60: {=_xlfn.IFS(N60="very good","15% increment",N60="good","12% increment",N60="average","10% increment")} -> 10% increment
A61: EMP-95489 | B61: KALPESH | C61: LAXMAN | D61: OSWAL | E61: 33761 | F61: 41034 | G61: 7 | H61: Loc-1003 | I61: NAGPUR | J61: 79711748xx | K61: Dept-101 | L61: PRODUCTION | M61: B.E | N61: Not Rated | O61: Male | Q61: =IF(N61="very poor","Terminate","Stay") -> Stay | R61: =IF(Logical!N61="very good","5% increment","no increment") -> no increment | S61: {=_xlfn.IFS(P61<40000,"low",P61>80000,"high",P61,"mid")} -> high | T61: =IF(AND(L61="hr",I61="mumbai"),"give work from home","no work from home") -> no work from home | U61: =IF(OR(L61="finance",Logical!L61="hr"),"give work from home","no work from home") -> no work from home | V61: {=_xlfn.IFS(N61="very good","15% increment",N61="good","12% increment",N61="average","10% increment")} -> #N/A
A62: EMP-95522 | B62: GOVIND | C62: M | D62: NOTANI | E62: 33791 | F62: 41004 | G62: 8 | H62: Loc-1004 | I62: MUMBAI | J62: 79720659xx | K62: Dept-105 | L62: ADMIN | M62: B.E | N62: Good | O62: Male | Q62: =IF(N62="very poor","Terminate","Stay") -> Stay | R62: =IF(Logical!N62="very good","5% increment","no increment") -> no increment | S62: {=_xlfn.IFS(P62<40000,"low",P62>80000,"high",P62,"mid")} -> high | T62: =IF(AND(L62="hr",I62="mumbai"),"give work from home","no work from home") -> no work from home | U62: =IF(OR(L62="finance",Logical!L62="hr"),"give work from home","no work from home") -> no work from home | V62: {=_xlfn.IFS(N62="very good","15% increment",N62="good","12% increment",N62="average","10% increment")} -> 12% increment
A63: EMP-95469 | B63: DEVIKA | C63: MADAN | D63: MURTHY | E63: 33853 | F63: 40944 | G63: 7 | H63: Loc-1002 | I63: BANGALORE | J63: 79738481xx | K63: Dept-105 | L63: ADMIN | M63: M.E | N63: Average | O63: Female | P63: 98689.59 | Q63: =IF(N63="very poor","Terminate","Stay") -> Stay | R63: =IF(Logical!N63="very good","5% increment","no increment") -> no increment | S63: {=_xlfn.IFS(P63<40000,"low",P63>80000,"high",P63,"mid")} -> high | T63: =IF(AND(L63="hr",I63="mumbai"),"give work from home","no work from home") -> no work from home | U63: =IF(OR(L63="finance",Logical!L63="hr"),"give work from home","no work from home") -> no work from home | V63: {=_xlfn.IFS(N63="very good","15% increment",N63="good","12% increment",N63="average","10% increment")} -> 10% increment
A64: EMP-95451 | B64: DISHA | C64: MADAN | D64: NAIK | E64: 33822 | F64: 40973 | G64: 6 | H64: Loc-1001 | I64: DELHI | J64: 79729570xx | K64: Dept-104 | L64: MARKETING | M64: MBA | N64: Good | O64: Female | P64: 53813.16 | Q64: =IF(N64="very poor","Terminate","Stay") -> Stay | R64: =IF(Logical!N64="very good","5% increment","no increment") -> no increment | S64: {=_xlfn.IFS(P64<40000,"low",P64>80000,"high",P64,"mid")} -> mid | T64: =IF(AND(L64="hr",I64="mumbai"),"give work from home","no work from home") -> no work from home | U64: =IF(OR(L64="finance",Logical!L64="hr"),"give work from home","no work from home") -> no work from home | V64: {=_xlfn.IFS(N64="very good","15% increment",N64="good","12% increment",N64="average","10% increment")} -> 12% increment
A65: EMP-95490 | B65: DARSHAN | C65: MADHAVRAO | D65: MUNDADA | E65: 33883 | F65: 40913 | G65: 8 | H65: Loc-1003 | I65: NAGPUR | J65: 79747392xx | K65: Dept-101 | L65: PRODUCTION | M65: MBA | N65: Not Rated | O65: Male | P65: 126117.9 | Q65: =IF(N65="very poor","Terminate","Stay") -> Stay | R65: =IF(Logical!N65="very good","5% increment","no increment") -> no increment | S65: {=_xlfn.IFS(P65<40000,"low",P65>80000,"high",P65,"mid")} -> high | T65: =IF(AND(L65="hr",I65="mumbai"),"give work from home","no work from home") -> no work from home | U65: =IF(OR(L65="finance",Logical!L65="hr"),"give work from home","no work from home") -> no work from home | V65: {=_xlfn.IFS(N65="very good","15% increment",N65="good","12% increment",N65="average","10% increment")} -> #N/A
A66: EMP-95523 | B66: CHAITANYA | C66: MAHAVIR | D66: MULIK | E66: 33914 | F66: 40882 | G66: 5 | H66: Loc-1004 | I66: MUMBAI | J66: 79756303xx | K66: Dept-103 | L66: FINANCE | M66: MCOM | N66: Poor | O66: Male | P66: 15809.49 | Q66: =IF(N66="very poor","Terminate","Stay") -> Stay | R66: =IF(Logical!N66="very good","5% increment","no increment") -> no increment | S66: {=_xlfn.IFS(P66<40000,"low",P66>80000,"high",P66,"mid")} -> low | T66: =IF(AND(L66="hr",I66="mumbai"),"give work from home","no work from home") -> no work from home | U66: =IF(OR(L66="finance",Logical!L66="hr"),"give work from home","no work from home") -> give work from home | V66: {=_xlfn.IFS(N66="very good","15% increment",N66="good","12% increment",N66="average","10% increment")} -> #N/A
A67: EMP-95580 | B67: ANOUSHKA | C67: MAHESH | D67: MIRAJKAR | E67: 33975 | F67: 40821 | G67: 7 | H67: Loc-1006 | I67: PUNE | J67: 79774124xx | K67: Dept-101 | L67: PRODUCTION | M67: MBA | N67: Average | O67: Female | P67: 103363.74 | Q67: =IF(N67="very poor","Terminate","Stay") -> Stay | R67: =IF(Logical!N67="very good","5% increment","no increment") -> no increment | S67: {=_xlfn.IFS(P67<40000,"low",P67>80000,"high",P67,"mid")} -> high | T67: =IF(AND(L67="hr",I67="mumbai"),"give work from home","no work from home") -> no work from home | U67: =IF(OR(L67="finance",Logical!L67="hr"),"give work from home","no work from home") -> no work from home | V67: {=_xlfn.IFS(N67="very good","15% increment",N67="good","12% increment",N67="average","10% increment")} -> 10% increment
A68: EMP-95559 | B68: BHAVESH | C68: MAHESH | D68: MORE | E68: 33944 | F68: 40852 | G68: 6 | H68: Loc-1005 | I68: CHENNAI | J68: 79765213xx | K68: Dept-101 | L68: PRODUCTION | M68: PGDBM | N68: Good | O68: Male | P68: 99038.43 | Q68: =IF(N68="very poor","Terminate","Stay") -> Stay | R68: =IF(Logical!N68="very good","5% increment","no increment") -> no increment | S68: {=_xlfn.IFS(P68<40000,"low",P68>80000,"high",P68,"mid")} -> high | T68: =IF(AND(L68="hr",I68="mumbai"),"give work from home","no work from home") -> no work from home | U68: =IF(OR(L68="finance",Logical!L68="hr"),"give work from home","no work from home") -> no work from home | V68: {=_xlfn.IFS(N68="very good","15% increment",N68="good","12% increment",N68="average","10% increment")} -> 12% increment
A69: EMP-95560 | B69: ANJALI | C69: MAHESHWARI | D69: MANGLANI | E69: 34006 | F69: 40791 | G69: 8 | H69: Loc-1005 | I69: CHENNAI | J69: 79783035xx | K69: Dept-103 | L69: FINANCE | M69: MBA | N69: Very Good | O69: Female | P69: 103172.49 | Q69: =IF(N69="very poor","Terminate","Stay") -> Stay | R69: =IF(Logical!N69="very good","5% increment","no increment") -> 5% increment | S69: {=_xlfn.IFS(P69<40000,"low",P69>80000,"high",P69,"mid")} -> high | T69: =IF(AND(L69="hr",I69="mumbai"),"give work from home","no work from home") -> no work from home | U69: =IF(OR(L69="finance",Logical!L69="hr"),"give work from home","no work from home") -> give work from home | V69: {=_xlfn.IFS(N69="very good","15% increment",N69="good","12% increment",N69="average","10% increment")} -> 15% increment
A70: EMP-95581 | B70: ANAGHA | C70: MANISH | D70: MANGHARAMANI | E70: 34034 | F70: 40760 | G70: 6 | H70: Loc-1006 | I70: PUNE | J70: 79791946xx | K70: Dept-101 | L70: PRODUCTION | M70: ICWA | N70: Good | O70: Female | P70: 93077.55 | Q70: =IF(N70="very poor","Terminate","Stay") -> Stay | R70: =IF(Logical!N70="very good","5% increment","no increment") -> no increment | S70: {=_xlfn.IFS(P70<40000,"low",P70>80000,"high",P70,"mid")} -> high | T70: =IF(AND(L70="hr",I70="mumbai"),"give work from home","no work from home") -> no work from home | U70: =IF(OR(L70="finance",Logical!L70="hr"),"give work from home","no work from home") -> no work from home | V70: {=_xlfn.IFS(N70="very good","15% increment",N70="good","12% increment",N70="average","10% increment")} -> 12% increment
A71: EMP-95524 | B71: AKASH | C71: MANOJ | D71: LOKHANDE | E71: 34126 | F71: 40668 | G71: 5 | H71: Loc-1004 | I71: MUMBAI | J71: 79818679xx | K71: Dept-103 | L71: FINANCE | M71: PGDBM | N71: Average | O71: Male | P71: 100762.74 | Q71: =IF(N71="very poor","Terminate","Stay") -> Stay | R71: =IF(Logical!N71="very good","5% increment","no increment") -> no increment | S71: {=_xlfn.IFS(P71<40000,"low",P71>80000,"high",P71,"mid")} -> high | T71: =IF(AND(L71="hr",I71="mumbai"),"give work from home","no work from home") -> no work from home | U71: =IF(OR(L71="finance",Logical!L71="hr"),"give work from home","no work from home") -> give work from home | V71: {=_xlfn.IFS(N71="very good","15% increment",N71="good","12% increment",N71="average","10% increment")} -> 10% increment
...
